Workbook

Sheet Letter Size
A1: Company Directory | I1: Update Date: Apr 28, 2026
A2: Ext | B2: Name / Office | C2: title / Address | D2: Personal Tel | E2: Direct Tel | F2: Email | H2: Meeting Room | I2: Ext
A3: =IF(LEN(ContactData!H2)<3,"",ContactData!H2) | B3: =ContactData!E2 -> LRI Head Office | C3: =ContactData!G2 -> 8 Steelcase Road West, Markham, ON, L3R 1B2 | D3: =IF(LEN(ContactData!I2)<3,"",ContactData!I2) | E3: =ContactData!J2 -> T: (905) 474-0590 | F3: =IF(LEN(ContactData!K2)<3,"",ContactData!K2) | H3: =ContactData!E80 -> Lunch Room | I3: =ContactData!H80 -> 541
A4: =IF(LEN(ContactData!H3)<3,"",ContactData!H3) -> 500 | B4: =ContactData!E3 -> Stephen Wong | C4: =ContactData!G3 -> Chairman | D4: =IF(LEN(ContactData!I3)<3,"",ContactData!I3) -> --- | E4: =ContactData!J3 -> (905) 752-3500 | F4: =IF(LEN(ContactData!K3)<3,"",ContactData!K3) -> stephenwong@livinggroupinc.com | H4: =ContactData!E81 -> Markham Room | I4: =ContactData!H81 -> 250
A5: =IF(LEN(ContactData!H4)<3,"",ContactData!H4) -> 511 | B5: =ContactData!E4 -> William Lau | C5: =ContactData!G4 -> President | D5: =IF(LEN(ContactData!I4)<3,"",ContactData!I4) -> (647) 918-9886 | E5: =ContactData!J4 -> (905) 752-3511 | F5: =IF(LEN(ContactData!K4)<3,"",ContactData!K4) -> williamlau@livinggroupinc.com | H5: =ContactData!E82 -> Mississauga Room | I5: =ContactData!H82 -> 226
A6: =IF(LEN(ContactData!H5)<3,"",ContactData!H5) -> 228 | B6: =ContactData!E5 -> Kelvin Wong | C6: =ContactData!G5 -> Broker of Record, Operating Principal | D6: =IF(LEN(ContactData!I5)<3,"",ContactData!I5) -> (416) 567-7882 | E6: =ContactData!J5 -> --- | F6: =IF(LEN(ContactData!K5)<3,"",ContactData!K5) -> kelvin@livingrealtykw.com | H6: =ContactData!E83 -> The Living Room | I6: =ContactData!H83 -> 288
A7: =IF(LEN(ContactData!H6)<3,"",ContactData!H6) -> 521 | B7: =ContactData!E6 -> Ben Wong | C7: =ContactData!G6 -> President & C.L.O. | D7: =IF(LEN(ContactData!I6)<3,"",ContactData!I6) -> (416) 399-2311 | E7: =ContactData!J6 -> (905) 752-3521 | F7: =IF(LEN(ContactData!K6)<3,"",ContactData!K6) -> benwong@livingrealtykw.com | H7: =ContactData!E84 -> Toronto Room | I7: =ContactData!H84 -> 208
A8: =IF(LEN(ContactData!H7)<3,"",ContactData!H7) -> 165 | B8: =ContactData!E7 -> David Wong | C8: =ContactData!G7 -> Vice President | D8: =IF(LEN(ContactData!I7)<3,"",ContactData!I7) -> (416) 230-8866 | E8: =ContactData!J7 -> (905) 752-3176 | F8: =IF(LEN(ContactData!K7)<3,"",ContactData!K7) -> davidwong@livingrealtykw.com | H8: =ContactData!E85 -> York Room | I8: =ContactData!H85 -> 524
A9: =IF(LEN(ContactData!H8)<3,"",ContactData!H8) -> 502 | B9: =ContactData!E8 -> Peter Woo | C9: =ContactData!G8 -> Broker of Record, Living Realty | D9: =IF(LEN(ContactData!I8)<3,"",ContactData!I8) -> (416) 569-6569 | E9: =ContactData!J8 -> (905) 752-3502 | F9: =IF(LEN(ContactData!K8)<3,"",ContactData!K8) -> pwoo@livinggroupinc.com
A10: =IF(LEN(ContactData!H9)<3,"",ContactData!H9) -> --- | B10: =ContactData!E9 -> Alan Cheung | C10: =ContactData!G9 -> Vice Presidnet, New Homes, Broker | D10: =IF(LEN(ContactData!I9)<3,"",ContactData!I9) -> (416) 669-0325 | E10: =ContactData!J9 -> --- | F10: =IF(LEN(ContactData!K9)<3,"",ContactData!K9) -> alancheung@livingrealtykw.com
A11: =IF(LEN(ContactData!H10)<3,"",ContactData!H10) -> --- | B11: =ContactData!E10 -> Andrew Chiang | C11: =ContactData!G10 -> Education and Training Co-ordinator | D11: =IF(LEN(ContactData!I10)<3,"",ContactData!I10) -> (647) 704-2388 | E11: =ContactData!J10 -> --- | F11: =IF(LEN(ContactData!K10)<3,"",ContactData!K10) -> andrewchiang@livingrealtykw.com
A12: =IF(LEN(ContactData!H11)<3,"",ContactData!H11) -> 509 | B12: =ContactData!E11 -> Rocky Chow | C12: =ContactData!G11 -> Executive Assistant to Chairman | D12: =IF(LEN(ContactData!I11)<3,"",ContactData!I11) -> (647) 818-1818 | E12: =ContactData!J11 -> --- | F12: =IF(LEN(ContactData!K11)<3,"",ContactData!K11) -> rockychow@livinggroupinc.com
A13: =IF(LEN(ContactData!H12)<3,"",ContactData!H12) -> 504 | B13: =ContactData!E12 -> Eddie Tang | C13: =ContactData!G12 -> Market Center Administrator, Executive Group Controller | D13: =IF(LEN(ContactData!I12)<3,"",ContactData!I12) -> (416) 723-8329 | E13: =ContactData!J12 -> (905) 752-3504 | F13: =IF(LEN(ContactData!K12)<3,"",ContactData!K12) -> eddietang@livingrealtykw.com
A14: =IF(LEN(ContactData!H13)<3,"",ContactData!H13) -> 514 | B14: =ContactData!E13 -> Winnie Tsui | C14: =ContactData!G13 -> Senior Manager, Accounting & Operations | D14: =IF(LEN(ContactData!I13)<3,"",ContactData!I13) -> (647) 286-0145 | E14: =ContactData!J13 -> (905) 752-3514 | F14: =IF(LEN(ContactData!K13)<3,"",ContactData!K13) -> winniet@livingproperties.com
A15: =IF(LEN(ContactData!H14)<3,"",ContactData!H14) -> 224 | B15: =ContactData!E14 -> Dan Flomen | C15: =ContactData!G14 -> Team Leader | D15: =IF(LEN(ContactData!I14)<3,"",ContactData!I14) -> --- | E15: =ContactData!J14 -> (905) 489-8989 | F15: =IF(LEN(ContactData!K14)<3,"",ContactData!K14) -> dan@livingrealtykw.com
A16: =IF(LEN(ContactData!H15)<3,"",ContactData!H15) -> 282 | B16: =ContactData!E15 -> Joanna Xie | C16: =ContactData!G15 -> Agent Services Coordinator | D16: =IF(LEN(ContactData!I15)<3,"",ContactData!I15) -> --- | E16: =ContactData!J15 -> --- | F16: =IF(LEN(ContactData!K15)<3,"",ContactData!K15) -> joannaxie@livingrealtykw.com
A17: =IF(LEN(ContactData!H16)<3,"",ContactData!H16) -> 123 | B17: =ContactData!E16 -> Wendy Chung | C17: =ContactData!G16 -> Administration Officer | D17: =IF(LEN(ContactData!I16)<3,"",ContactData!I16) -> --- | E17: =ContactData!J16 -> --- | F17: =IF(LEN(ContactData!K16)<3,"",ContactData!K16) -> wendychung@livingrealtykw.com
A18: =IF(LEN(ContactData!H17)<3,"",ContactData!H17) -> 206 | B18: =ContactData!E17 -> Benjamin Wong | C18: =ContactData!G17 -> Assistant to the Broker of Record | D18: =IF(LEN(ContactData!I17)<3,"",ContactData!I17) -> --- | E18: =ContactData!J17 -> --- | F18: =IF(LEN(ContactData!K17)<3,"",ContactData!K17) -> benjaminwongici@livingrealtykw.com
A19: =IF(LEN(ContactData!H18)<3,"",ContactData!H18) -> 507 | B19: =ContactData!E18 -> Luvie Chao | C19: =ContactData!G18 -> Senior Deal Administrator | D19: =IF(LEN(ContactData!I18)<3,"",ContactData!I18) -> --- | E19: =ContactData!J18 -> (905) 752-3507 | F19: =IF(LEN(ContactData!K18)<3,"",ContactData!K18) -> luvie@livingrealtykw.com
A20: =IF(LEN(ContactData!H19)<3,"",ContactData!H19) -> 508 | B20: =ContactData!E19 -> Maria Leung | C20: =ContactData!G19 -> Deal Administrator | D20: =IF(LEN(ContactData!I19)<3,"",ContactData!I19) -> --- | E20: =ContactData!J19 -> (905) 752-3508 | F20: =IF(LEN(ContactData!K19)<3,"",ContactData!K19) -> marialeung@livingrealtykw.com
... A80: =IF(LEN(ContactData!H79)<3,"",ContactData!H79) -> 187 | B80: =ContactData!E79 -> Lily Hou | C80: =ContactData!G79 -> Senior Accounting Analyst & Operations Support | D80: =IF(LEN(ContactData!I79)<3,"",ContactData!I79) -> (647) 774-8994 | E80: =ContactData!J79 -> --- | F80: =IF(LEN(ContactData!K79)<3,"",ContactData!K79) -> lily@ihmg.ca

Sheet Legal Size
A1: Company Directory | F1: Update Date: Apr 28, 2026
A2: Ext | B2: Name / Office | C2: title / Address | D2: Personal Tel | E2: Direct Tel | F2: Email
A3: =IF(LEN(ContactData!H2)<3,"",ContactData!H2) | B3: =ContactData!E2 -> LRI Head Office | C3: =ContactData!G2 -> 8 Steelcase Road West, Markham, ON, L3R 1B2 | D3: =IF(LEN(ContactData!I2)<3,"",ContactData!I2) | E3: =ContactData!J2 -> T: (905) 474-0590 | F3: =IF(LEN(ContactData!K2)<3,"",ContactData!K2)
A4: =IF(LEN(ContactData!H3)<3,"",ContactData!H3) -> 500 | B4: =ContactData!E3 -> Stephen Wong | C4: =ContactData!G3 -> Chairman | D4: =IF(LEN(ContactData!I3)<3,"",ContactData!I3) -> --- | E4: =ContactData!J3 -> (905) 752-3500 | F4: =IF(LEN(ContactData!K3)<3,"",ContactData!K3) -> stephenwong@livinggroupinc.com
A5: =IF(LEN(ContactData!H4)<3,"",ContactData!H4) -> 511 | B5: =ContactData!E4 -> William Lau | C5: =ContactData!G4 -> President | D5: =IF(LEN(ContactData!I4)<3,"",ContactData!I4) -> (647) 918-9886 | E5: =ContactData!J4 -> (905) 752-3511 | F5: =IF(LEN(ContactData!K4)<3,"",ContactData!K4) -> williamlau@livinggroupinc.com
A6: =IF(LEN(ContactData!H5)<3,"",ContactData!H5) -> 228 | B6: =ContactData!E5 -> Kelvin Wong | C6: =ContactData!G5 -> Broker of Record, Operating Principal | D6: =IF(LEN(ContactData!I5)<3,"",ContactData!I5) -> (416) 567-7882 | E6: =ContactData!J5 -> --- | F6: =IF(LEN(ContactData!K5)<3,"",ContactData!K5) -> kelvin@livingrealtykw.com
A7: =IF(LEN(ContactData!H6)<3,"",ContactData!H6) -> 521 | B7: =ContactData!E6 -> Ben Wong | C7: =ContactData!G6 -> President & C.L.O. | D7: =IF(LEN(ContactData!I6)<3,"",ContactData!I6) -> (416) 399-2311 | E7: =ContactData!J6 -> (905) 752-3521 | F7: =IF(LEN(ContactData!K6)<3,"",ContactData!K6) -> benwong@livingrealtykw.com
A8: =IF(LEN(ContactData!H7)<3,"",ContactData!H7) -> 165 | B8: =ContactData!E7 -> David Wong | C8: =ContactData!G7 -> Vice President | D8: =IF(LEN(ContactData!I7)<3,"",ContactData!I7) -> (416) 230-8866 | E8: =ContactData!J7 -> (905) 752-3176 | F8: =IF(LEN(ContactData!K7)<3,"",ContactData!K7) -> davidwong@livingrealtykw.com
A9: =IF(LEN(ContactData!H8)<3,"",ContactData!H8) -> 502 | B9: =ContactData!E8 -> Peter Woo | C9: =ContactData!G8 -> Broker of Record, Living Realty | D9: =IF(LEN(ContactData!I8)<3,"",ContactData!I8) -> (416) 569-6569 | E9: =ContactData!J8 -> (905) 752-3502 | F9: =IF(LEN(ContactData!K8)<3,"",ContactData!K8) -> pwoo@livinggroupinc.com
A10: =IF(LEN(ContactData!H9)<3,"",ContactData!H9) -> --- | B10: =ContactData!E9 -> Alan Cheung | C10: =ContactData!G9 -> Vice Presidnet, New Homes, Broker | D10: =IF(LEN(ContactData!I9)<3,"",ContactData!I9) -> (416) 669-0325 | E10: =ContactData!J9 -> --- | F10: =IF(LEN(ContactData!K9)<3,"",ContactData!K9) -> alancheung@livingrealtykw.com
A11: =IF(LEN(ContactData!H10)<3,"",ContactData!H10) -> --- | B11: =ContactData!E10 -> Andrew Chiang | C11: =ContactData!G10 -> Education and Training Co-ordinator | D11: =IF(LEN(ContactData!I10)<3,"",ContactData!I10) -> (647) 704-2388 | E11: =ContactData!J10 -> --- | F11: =IF(LEN(ContactData!K10)<3,"",ContactData!K10) -> andrewchiang@livingrealtykw.com
A12: =IF(LEN(ContactData!H11)<3,"",ContactData!H11) -> 509 | B12: =ContactData!E11 -> Rocky Chow | C12: =ContactData!G11 -> Executive Assistant to Chairman | D12: =IF(LEN(ContactData!I11)<3,"",ContactData!I11) -> (647) 818-1818 | E12: =ContactData!J11 -> --- | F12: =IF(LEN(ContactData!K11)<3,"",ContactData!K11) -> rockychow@livinggroupinc.com
A13: =IF(LEN(ContactData!H12)<3,"",ContactData!H12) -> 504 | B13: =ContactData!E12 -> Eddie Tang | C13: =ContactData!G12 -> Market Center Administrator, Executive Group Controller | D13: =IF(LEN(ContactData!I12)<3,"",ContactData!I12) -> (416) 723-8329 | E13: =ContactData!J12 -> (905) 752-3504 | F13: =IF(LEN(ContactData!K12)<3,"",ContactData!K12) -> eddietang@livingrealtykw.com
A14: =IF(LEN(ContactData!H13)<3,"",ContactData!H13) -> 514 | B14: =ContactData!E13 -> Winnie Tsui | C14: =ContactData!G13 -> Senior Manager, Accounting & Operations | D14: =IF(LEN(ContactData!I13)<3,"",ContactData!I13) -> (647) 286-0145 | E14: =ContactData!J13 -> (905) 752-3514 | F14: =IF(LEN(ContactData!K13)<3,"",ContactData!K13) -> winniet@livingproperties.com
... A80: =IF(LEN(ContactData!H79)<3,"",ContactData!H79) -> 187 | B80: =ContactData!E79 -> Lily Hou | C80: =ContactData!G79 -> Senior Accounting Analyst & Operations Support | D80: =IF(LEN(ContactData!I79)<3,"",ContactData!I79) -> (647) 774-8994 | E80: =ContactData!J79 -> --- | F80: =IF(LEN(ContactData!K79)<3,"",ContactData!K79) -> lily@ihmg.ca

Sheet ContactData
A1: DisplayOrder | B1: OfficeCode | C1: OfficeName | D1: Office_id | E1: DisplayName | F1: AgentList | G1: Title | H1: Ext | I1: PersonalTel | J1: DirectTel | K1: Email | L1: ContactType | M1: SQL Statement
A2: 1 | B2: RHO | C2: LRI HO | D2: 1 | E2: LRI Head Office | G2: 8 Steelcase Road West, Markham, ON, L3R 1B2 | H2: -- | I2: -- | J2: T: (905) 474-0590 | K2: -- | L2: Office Header | M2: ="INSERT INTO `directory` (`order`, `office`, `displayname`, `title`, `ext`, `personalTel`, `directTel`, `email`, `contacttype`) VALUES ('" & A2 & "','" & D2 & "','" & E2 & "','" & G2 & "','" & H2 & "','" & I2 & "','" & J2 & "','" & K2 & "','" & L2 & "');" -> INSERT INTO `directory` (`order`, `office`, `displayname`, `title`, `ext`, `personalTel`, `directTel`, `email`, `contacttype`) VALUES ('1','1','LRI Head Office','8 Steelcase Road West, Markham, ON, L3R 1B2','--','--','T: (905) 474-0590','--','Office Header');
A3: 2 | B3: RHO | C3: LRI HO | D3: 1 | E3: Stephen Wong | F3: Y | G3: Chairman | H3: 500 | I3: --- | J3: (905) 752-3500 | K3: stephenwong@livinggroupinc.com | L3: Staff | M3: ="INSERT INTO `directory` (`order`, `office`, `displayname`, `title`, `ext`, `personalTel`, `directTel`, `email`, `contacttype`) VALUES ('" & A3 & "','" & D3 & "','" & E3 & "','" & G3 & "','" & H3 & "','" & I3 & "','" & J3 & "','" & K3 & "','" & L3 & "');" -> INSERT INTO `directory` (`order`, `office`, `displayname`, `title`, `ext`, `personalTel`, `directTel`, `email`, `contacttype`) VALUES ('2','1','Stephen Wong','Chairman','500','---','(905) 752-3500','stephenwong@livinggroupinc.com','Staff');
A4: 3 | B4: RHO | C4: LRI HO | D4: 1 | E4: William Lau | F4: Y | G4: President | H4: 511 | I4: (647) 918-9886 | J4: (905) 752-3511 | K4: williamlau@livinggroupinc.com | L4: Staff | M4: ="INSERT INTO `directory` (`order`, `office`, `displayname`, `title`, `ext`, `personalTel`, `directTel`, `email`, `contacttype`) VALUES ('" & A4 & "','" & D4 & "','" & E4 & "','" & G4 & "','" & H4 & "','" & I4 & "','" & J4 & "','" & K4 & "','" & L4 & "');" -> INSERT INTO `directory` (`order`, `office`, `displayname`, `title`, `ext`, `personalTel`, `directTel`, `email`, `contacttype`) VALUES ('3','1','William Lau','President','511','(647) 918-9886','(905) 752-3511','williamlau@livinggroupinc.com','Staff');
A5: 4 | B5: RHO | C5: LRI HO | D5: 1 | E5: Kelvin Wong | F5: Y | G5: Broker of Record, Operating Principal | H5: 228 | I5: (416) 567-7882 | J5: --- | K5: kelvin@livingrealtykw.com | L5: Staff | M5: ="INSERT INTO `directory` (`order`, `office`, `displayname`, `title`, `ext`, `personalTel`, `directTel`, `email`, `contacttype`) VALUES ('" & A5 & "','" & D5 & "','" & E5 & "','" & G5 & "','" & H5 & "','" & I5 & "','" & J5 & "','" & K5 & "','" & L5 & "');" -> INSERT INTO `directory` (`order`, `office`, `displayname`, `title`, `ext`, `personalTel`, `directTel`, `email`, `contacttype`) VALUES ('4','1','Kelvin Wong','Broker of Record, Operating Principal','228','(416) 567-7882','---','kelvin@livingrealtykw.com','Staff');
A6: 5 | B6: RHO | C6: LRI HO | D6: 1 | E6: Ben Wong | F6: Y | G6: President & C.L.O. | H6: 521 | I6: (416) 399-2311 | J6: (905) 752-3521 | K6: benwong@livingrealtykw.com | L6: Staff | M6: ="INSERT INTO `directory` (`order`, `office`, `displayname`, `title`, `ext`, `personalTel`, `directTel`, `email`, `contacttype`) VALUES ('" & A6 & "','" & D6 & "','" & E6 & "','" & G6 & "','" & H6 & "','" & I6 & "','" & J6 & "','" & K6 & "','" & L6 & "');" -> INSERT INTO `directory` (`order`, `office`, `displayname`, `title`, `ext`, `personalTel`, `directTel`, `email`, `contacttype`) VALUES ('5','1','Ben Wong','President & C.L.O.','521','(416) 399-2311','(905) 752-3521','benwong@livingrealtykw.com','Staff');
A7: 6 | B7: RHO | C7: LRI HO | D7: 1 | E7: David Wong | F7: Y | G7: Vice President | H7: 165 | I7: (416) 230-8866 | J7: (905) 752-3176 | K7: davidwong@livingrealtykw.com | L7: Staff | M7: ="INSERT INTO `directory` (`order`, `office`, `displayname`, `title`, `ext`, `personalTel`, `directTel`, `email`, `contacttype`) VALUES ('" & A7 & "','" & D7 & "','" & E7 & "','" & G7 & "','" & H7 & "','" & I7 & "','" & J7 & "','" & K7 & "','" & L7 & "');" -> INSERT INTO `directory` (`order`, `office`, `displayname`, `title`, `ext`, `personalTel`, `directTel`, `email`, `contacttype`) VALUES ('6','1','David Wong','Vice President','165','(416) 230-8866','(905) 752-3176','davidwong@livingrealtykw.com','Staff');
A8: 7 | B8: RHO | C8: LRI HO | D8: 1 | E8: Peter Woo | F8: Y | G8: Broker of Record, Living Realty | H8: 502 | I8: (416) 569-6569 | J8: (905) 752-3502 | K8: pwoo@livinggroupinc.com | L8: Staff | M8: ="INSERT INTO `directory` (`order`, `office`, `displayname`, `title`, `ext`, `personalTel`, `directTel`, `email`, `contacttype`) VALUES ('" & A8 & "','" & D8 & "','" & E8 & "','" & G8 & "','" & H8 & "','" & I8 & "','" & J8 & "','" & K8 & "','" & L8 & "');" -> INSERT INTO `directory` (`order`, `office`, `displayname`, `title`, `ext`, `personalTel`, `directTel`, `email`, `contacttype`) VALUES ('7','1','Peter Woo','Broker of Record, Living Realty','502','(416) 569-6569','(905) 752-3502','pwoo@livinggroupinc.com','Staff');
A9: 8 | B9: RHO | C9: LRI HO | D9: 1 | E9: Alan Cheung | F9: Y | G9: Vice Presidnet, New Homes, Broker | H9: --- | I9: (416) 669-0325 | J9: --- | K9: alancheung@livingrealtykw.com | L9: Staff | M9: ="INSERT INTO `directory` (`order`, `office`, `displayname`, `title`, `ext`, `personalTel`, `directTel`, `email`, `contacttype`) VALUES ('" & A9 & "','" & D9 & "','" & E9 & "','" & G9 & "','" & H9 & "','" & I9 & "','" & J9 & "','" & K9 & "','" & L9 & "');" -> INSERT INTO `directory` (`order`, `office`, `displayname`, `title`, `ext`, `personalTel`, `directTel`, `email`, `contacttype`) VALUES ('8','1','Alan Cheung','Vice Presidnet, New Homes, Broker','---','(416) 669-0325','---','alancheung@livingrealtykw.com','Staff');
A10: 9 | B10: RHO | C10: LRI HO | D10: 1 | E10: Andrew Chiang | F10: Y | G10: Education and Training Co-ordinator | H10: --- | I10: (647) 704-2388 | J10: --- | K10: andrewchiang@livingrealtykw.com | L10: Staff | M10: ="INSERT INTO `directory` (`order`, `office`, `displayname`, `title`, `ext`, `personalTel`, `directTel`, `email`, `contacttype`) VALUES ('" & A10 & "','" & D10 & "','" & E10 & "','" & G10 & "','" & H10 & "','" & I10 & "','" & J10 & "','" & K10 & "','" & L10 & "');" -> INSERT INTO `directory` (`order`, `office`, `displayname`, `title`, `ext`, `personalTel`, `directTel`, `email`, `contacttype`) VALUES ('9','1','Andrew Chiang','Education and Training Co-ordinator','---','(647) 704-2388','---','andrewchiang@livingrealtykw.com','Staff');
A11: 10 | B11: RHO | C11: LRI HO | D11: 1 | E11: Rocky Chow | F11: Y | G11: Executive Assistant to Chairman | H11: 509 | I11: (647) 818-1818 | J11: --- | K11: rockychow@livinggroupinc.com | L11: Staff | M11: ="INSERT INTO `directory` (`order`, `office`, `displayname`, `title`, `ext`, `personalTel`, `directTel`, `email`, `contacttype`) VALUES ('" & A11 & "','" & D11 & "','" & E11 & "','" & G11 & "','" & H11 & "','" & I11 & "','" & J11 & "','" & K11 & "','" & L11 & "');" -> INSERT INTO `directory` (`order`, `office`, `displayname`, `title`, `ext`, `personalTel`, `directTel`, `email`, `contacttype`) VALUES ('10','1','Rocky Chow','Executive Assistant to Chairman','509','(647) 818-1818','---','rockychow@livinggroupinc.com','Staff');
A12: 11 | B12: RHO | C12: LRI HO | D12: 1 | E12: Eddie Tang | G12: Market Center Administrator, Executive Group Controller | H12: 504 | I12: (416) 723-8329 | J12: (905) 752-3504 | K12: eddietang@livingrealtykw.com | L12: Staff | M12: ="INSERT INTO `directory` (`order`, `office`, `displayname`, `title`, `ext`, `personalTel`, `directTel`, `email`, `contacttype`) VALUES ('" & A12 & "','" & D12 & "','" & E12 & "','" & G12 & "','" & H12 & "','" & I12 & "','" & J12 & "','" & K12 & "','" & L12 & "');" -> INSERT INTO `directory` (`order`, `office`, `displayname`, `title`, `ext`, `personalTel`, `directTel`, `email`, `contacttype`) VALUES ('11','1','Eddie Tang','Market Center Administrator, Executive Group Controller','504','(416) 723-8329','(905) 752-3504','eddietang@livingrealtykw.com','Staff');
A13: 12 | B13: RHO | C13: LRI HO | D13: 1 | E13: Winnie Tsui | F13: Y | G13: Senior Manager, Accounting & Operations | H13: 514 | I13: (647) 286-0145 | J13: (905) 752-3514 | K13: winniet@livingproperties.com | L13: Staff | M13: ="INSERT INTO `directory` (`order`, `office`, `displayname`, `title`, `ext`, `personalTel`, `directTel`, `email`, `contacttype`) VALUES ('" & A13 & "','" & D13 & "','" & E13 & "','" & G13 & "','" & H13 & "','" & I13 & "','" & J13 & "','" & K13 & "','" & L13 & "');" -> INSERT INTO `directory` (`order`, `office`, `displayname`, `title`, `ext`, `personalTel`, `directTel`, `email`, `contacttype`) VALUES ('12','1','Winnie Tsui','Senior Manager, Accounting & Operations','514','(647) 286-0145','(905) 752-3514','winniet@livingproperties.com','Staff');
A14: 13 | B14: RHO | C14: LRI HO | D14: 1 | E14: Dan Flomen | F14: Y | G14: Team Leader | H14: 224 | I14: --- | J14: (905) 489-8989 | K14: dan@livingrealtykw.com | L14: Staff | M14: ="INSERT INTO `directory` (`order`, `office`, `displayname`, `title`, `ext`, `personalTel`, `directTel`, `email`, `contacttype`) VALUES ('" & A14 & "','" & D14 & "','" & E14 & "','" & G14 & "','" & H14 & "','" & I14 & "','" & J14 & "','" & K14 & "','" & L14 & "');" -> INSERT INTO `directory` (`order`, `office`, `displayname`, `title`, `ext`, `personalTel`, `directTel`, `email`, `contacttype`) VALUES ('13','1','Dan Flomen','Team Leader','224','---','(905) 489-8989','dan@livingrealtykw.com','Staff');
A15: 14 | B15: RHO | C15: LRI HO | D15: 1 | E15: Joanna Xie | F15: Y | G15: Agent Services Coordinator | H15: 282 | I15: --- | J15: --- | K15: joannaxie@livingrealtykw.com | L15: Staff | M15: ="INSERT INTO `directory` (`order`, `office`, `displayname`, `title`, `ext`, `personalTel`, `directTel`, `email`, `contacttype`) VALUES ('" & A15 & "','" & D15 & "','" & E15 & "','" & G15 & "','" & H15 & "','" & I15 & "','" & J15 & "','" & K15 & "','" & L15 & "');" -> INSERT INTO `directory` (`order`, `office`, `displayname`, `title`, `ext`, `personalTel`, `directTel`, `email`, `contacttype`) VALUES ('14','1','Joanna Xie','Agent Services Coordinator','282','---','---','joannaxie@livingrealtykw.com','Staff');
A16: 15 | B16: RHO | C16: LRI HO | D16: 1 | E16: Wendy Chung | F16: Y | G16: Administration Officer | H16: 123 | I16: --- | J16: --- | K16: wendychung@livingrealtykw.com | L16: Staff | M16: ="INSERT INTO `directory` (`order`, `office`, `displayname`, `title`, `ext`, `personalTel`, `directTel`, `email`, `contacttype`) VALUES ('" & A16 & "','" & D16 & "','" & E16 & "','" & G16 & "','" & H16 & "','" & I16 & "','" & J16 & "','" & K16 & "','" & L16 & "');" -> INSERT INTO `directory` (`order`, `office`, `displayname`, `title`, `ext`, `personalTel`, `directTel`, `email`, `contacttype`) VALUES ('15','1','Wendy Chung','Administration Officer ','123','---','---','wendychung@livingrealtykw.com','Staff');
A17: 16 | B17: RHO | C17: LRI HO | D17: 1 | E17: Benjamin Wong | F17: Y | G17: Assistant to the Broker of Record | H17: 206 | I17: --- | J17: --- | K17: benjaminwongici@livingrealtykw.com | L17: Staff | M17: ="INSERT INTO `directory` (`order`, `office`, `displayname`, `title`, `ext`, `personalTel`, `directTel`, `email`, `contacttype`) VALUES ('" & A17 & "','" & D17 & "','" & E17 & "','" & G17 & "','" & H17 & "','" & I17 & "','" & J17 & "','" & K17 & "','" & L17 & "');" -> INSERT INTO `directory` (`order`, `office`, `displayname`, `title`, `ext`, `personalTel`, `directTel`, `email`, `contacttype`) VALUES ('16','1','Benjamin Wong','Assistant to the Broker of Record','206','---','---','benjaminwongici@livingrealtykw.com','Staff');
A18: 17 | B18: RHO | C18: LRI HO | D18: 1 | E18: Luvie Chao | F18: Y | G18: Senior Deal Administrator | H18: 507 | I18: --- | J18: (905) 752-3507 | K18: luvie@livingrealtykw.com | L18: Staff | M18: ="INSERT INTO `directory` (`order`, `office`, `displayname`, `title`, `ext`, `personalTel`, `directTel`, `email`, `contacttype`) VALUES ('" & A18 & "','" & D18 & "','" & E18 & "','" & G18 & "','" & H18 & "','" & I18 & "','" & J18 & "','" & K18 & "','" & L18 & "');" -> INSERT INTO `directory` (`order`, `office`, `displayname`, `title`, `ext`, `personalTel`, `directTel`, `email`, `contacttype`) VALUES ('17','1','Luvie Chao','Senior Deal Administrator','507','---','(905) 752-3507','luvie@livingrealtykw.com','Staff');
A19: 18 | B19: RHO | C19: LRI HO | D19: 1 | E19: Maria Leung | F19: Y | G19: Deal Administrator | H19: 508 | I19: --- | J19: (905) 752-3508 | K19: marialeung@livingrealtykw.com | L19: Staff | M19: ="INSERT INTO `directory` (`order`, `office`, `displayname`, `title`, `ext`, `personalTel`, `directTel`, `email`, `contacttype`) VALUES ('" & A19 & "','" & D19 & "','" & E19 & "','" & G19 & "','" & H19 & "','" & I19 & "','" & J19 & "','" & K19 & "','" & L19 & "');" -> INSERT INTO `directory` (`order`, `office`, `displayname`, `title`, `ext`, `personalTel`, `directTel`, `email`, `contacttype`) VALUES ('18','1','Maria Leung','Deal Administrator','508','---','(905) 752-3508','marialeung@livingrealtykw.com','Staff');
A20: 19 | B20: RHO | C20: LRI HO | D20: 1 | E20: Ken Cheung | F20: Y | G20: Deal Administrator | H20: 255 | I20: --- | J20: --- | K20: kencheung@livingrealtykw.com | L20: Staff | M20: ="INSERT INTO `directory` (`order`, `office`, `displayname`, `title`, `ext`, `personalTel`, `directTel`, `email`, `contacttype`) VALUES ('" & A20 & "','" & D20 & "','" & E20 & "','" & G20 & "','" & H20 & "','" & I20 & "','" & J20 & "','" & K20 & "','" & L20 & "');" -> INSERT INTO `directory` (`order`, `office`, `displayname`, `title`, `ext`, `personalTel`, `directTel`, `email`, `contacttype`) VALUES ('19','1','Ken Cheung','Deal Administrator','255','---','---','kencheung@livingrealtykw.com','Staff');
A21: 20 | B21: RHO | C21: LRI HO | D21: 1 | E21: Connie Cheung | F21: Y | G21: Accounting Bookkeeper | H21: 506 | I21: --- | J21: (905) 752-3506 | K21: conniecheung@livingrealtykw.com | L21: Staff | M21: ="INSERT INTO `directory` (`order`, `office`, `displayname`, `title`, `ext`, `personalTel`, `directTel`, `email`, `contacttype`) VALUES ('" & A21 & "','" & D21 & "','" & E21 & "','" & G21 & "','" & H21 & "','" & I21 & "','" & J21 & "','" & K21 & "','" & L21 & "');" -> INSERT INTO `directory` (`order`, `office`, `displayname`, `title`, `ext`, `personalTel`, `directTel`, `email`, `contacttype`) VALUES ('20','1','Connie Cheung','Accounting Bookkeeper','506','---','(905) 752-3506','conniecheung@livingrealtykw.com','Staff');
A22: 21 | B22: RHO | C22: LRI HO | D22: 1 | E22: Simon Chan | F22: Y | G22: Operations Assistant | H22: 519 | I22: --- | J22: (905) 752-3519 | K22: simonchan@livingrealtykw.com | L22: Staff | M22: ="INSERT INTO `directory` (`order`, `office`, `displayname`, `title`, `ext`, `personalTel`, `directTel`, `email`, `contacttype`) VALUES ('" & A22 & "','" & D22 & "','" & E22 & "','" & G22 & "','" & H22 & "','" & I22 & "','" & J22 & "','" & K22 & "','" & L22 & "');" -> INSERT INTO `directory` (`order`, `office`, `displayname`, `title`, `ext`, `personalTel`, `directTel`, `email`, `contacttype`) VALUES ('21','1','Simon Chan','Operations Assistant','519','---','(905) 752-3519','simonchan@livingrealtykw.com','Staff');
A23: 22 | B23: RHO | C23: LRI HO | D23: 1 | E23: Kelly Wan | F23: Y | G23: Digital Artist & Content Creator | H23: 121 | I23: --- | J23: --- | K23: kellywan@livingrealtykw.com | L23: Staff | M23: ="INSERT INTO `directory` (`order`, `office`, `displayname`, `title`, `ext`, `personalTel`, `directTel`, `email`, `contacttype`) VALUES ('" & A23 & "','" & D23 & "','" & E23 & "','" & G23 & "','" & H23 & "','" & I23 & "','" & J23 & "','" & K23 & "','" & L23 & "');" -> INSERT INTO `directory` (`order`, `office`, `displayname`, `title`, `ext`, `personalTel`, `directTel`, `email`, `contacttype`) VALUES ('22','1','Kelly Wan','Digital Artist & Content Creator ','121','---','---','kellywan@livingrealtykw.com','Staff');
A24: 23 | B24: RHO | C24: LRI HO | D24: 1 | E24: Nelson Lau | F24: Y | G24: Senior Technical Specialist & System Architech | H24: 522 | I24: (647) 701-8828 | J24: (905) 752-3522 | K24: nelsonlau@livingrealtykw.com | L24: Staff | M24: ="INSERT INTO `directory` (`order`, `office`, `displayname`, `title`, `ext`, `personalTel`, `directTel`, `email`, `contacttype`) VALUES ('" & A24 & "','" & D24 & "','" & E24 & "','" & G24 & "','" & H24 & "','" & I24 & "','" & J24 & "','" & K24 & "','" & L24 & "');" -> INSERT INTO `directory` (`order`, `office`, `displayname`, `title`, `ext`, `personalTel`, `directTel`, `email`, `contacttype`) VALUES ('23','1','Nelson Lau','Senior Technical Specialist & System Architech','522','(647) 701-8828','(905) 752-3522','nelsonlau@livingrealtykw.com','Staff');
A25: 24 | B25: RHO | C25: LRI HO | D25: 1 | E25: IT Support | G25: Information Technology Technical Support | H25: 522 | I25: --- | J25: (905) 752-3522 | K25: itsupport@livingrealtykw.com | L25: Staff | M25: ="INSERT INTO `directory` (`order`, `office`, `displayname`, `title`, `ext`, `personalTel`, `directTel`, `email`, `contacttype`) VALUES ('" & A25 & "','" & D25 & "','" & E25 & "','" & G25 & "','" & H25 & "','" & I25 & "','" & J25 & "','" & K25 & "','" & L25 & "');" -> INSERT INTO `directory` (`order`, `office`, `displayname`, `title`, `ext`, `personalTel`, `directTel`, `email`, `contacttype`) VALUES ('24','1','IT Support','Information Technology Technical Support','522','---','(905) 752-3522','itsupport@livingrealtykw.com','Staff');
A26: 25 | B26: NM | C26: LRI NM | D26: 2 | E26: North Markham Office | F26: Y | G26: 735 Markland St, Unit 12&13, Markham, ON, L6C 0G6 | H26: -- | I26: -- | J26: T: (905) 888-8188 | K26: northmarkham@livingrealtykw.com | L26: Office Header | M26: ="INSERT INTO `directory` (`order`, `office`, `displayname`, `title`, `ext`, `personalTel`, `directTel`, `email`, `contacttype`) VALUES ('" & A26 & "','" & D26 & "','" & E26 & "','" & G26 & "','" & H26 & "','" & I26 & "','" & J26 & "','" & K26 & "','" & L26 & "');" -> INSERT INTO `directory` (`order`, `office`, `displayname`, `title`, `ext`, `personalTel`, `directTel`, `email`, `contacttype`) VALUES ('25','2','North Markham Office','735 Markland St, Unit 12&13, Markham, ON, L6C 0G6','--','--','T: (905) 888-8188','northmarkham@livingrealtykw.com','Office Header');
A27: 26 | B27: NM | C27: LRI NM | D27: 2 | E27: Chris Tam | F27: Y | G27: Manager North Markham Branch | H27: --- | I27: (416) 505-6625 | J27: --- | K27: christam@livingrealtykw.com | L27: Staff | M27: ="INSERT INTO `directory` (`order`, `office`, `displayname`, `title`, `ext`, `personalTel`, `directTel`, `email`, `contacttype`) VALUES ('" & A27 & "','" & D27 & "','" & E27 & "','" & G27 & "','" & H27 & "','" & I27 & "','" & J27 & "','" & K27 & "','" & L27 & "');" -> INSERT INTO `directory` (`order`, `office`, `displayname`, `title`, `ext`, `personalTel`, `directTel`, `email`, `contacttype`) VALUES ('26','2','Chris Tam','Manager North Markham Branch','---','(416) 505-6625','---','christam@livingrealtykw.com','Staff');
A28: 27 | B28: NM | C28: LRI NM | D28: 2 | E28: Grace Chui | F28: Y | G28: Head Secretary | H28: --- | I28: --- | J28: (905) 888-8188 | K28: gracemschui@livingrealtykw.com | L28: Staff | M28: ="INSERT INTO `directory` (`order`, `office`, `displayname`, `title`, `ext`, `personalTel`, `directTel`, `email`, `contacttype`) VALUES ('" & A28 & "','" & D28 & "','" & E28 & "','" & G28 & "','" & H28 & "','" & I28 & "','" & J28 & "','" & K28 & "','" & L28 & "');" -> INSERT INTO `directory` (`order`, `office`, `displayname`, `title`, `ext`, `personalTel`, `directTel`, `email`, `contacttype`) VALUES ('27','2','Grace Chui','Head Secretary','---','---','(905) 888-8188','gracemschui@livingrealtykw.com','Staff');
A29: 28 | B29: NM | C29: LRI NM | D29: 2 | E29: Kiran Li | F29: Y | G29: Secretary | H29: --- | I29: --- | J29: (905) 888-8188 | K29: kiranli@livingrealtykw.com | L29: Staff | M29: ="INSERT INTO `directory` (`order`, `office`, `displayname`, `title`, `ext`, `personalTel`, `directTel`, `email`, `contacttype`) VALUES ('" & A29 & "','" & D29 & "','" & E29 & "','" & G29 & "','" & H29 & "','" & I29 & "','" & J29 & "','" & K29 & "','" & L29 & "');" -> INSERT INTO `directory` (`order`, `office`, `displayname`, `title`, `ext`, `personalTel`, `directTel`, `email`, `contacttype`) VALUES ('28','2','Kiran Li','Secretary','---','---','(905) 888-8188','kiranli@livingrealtykw.com','Staff');
A30: 29 | B30: MS | C30: LRI MS | D30: 4 | E30: Mississauga Office | F30: Y | G30: 1177 Central Parkway West, Golden Square, Unit 32, Mississauga, ON, L5C 4P3 | H30: -- | I30: -- | J30: T: (905) 896-0002 | K30: mississauga@livingrealtykw.com | L30: Office Header | M30: ="INSERT INTO `directory` (`order`, `office`, `displayname`, `title`, `ext`, `personalTel`, `directTel`, `email`, `contacttype`) VALUES ('" & A30 & "','" & D30 & "','" & E30 & "','" & G30 & "','" & H30 & "','" & I30 & "','" & J30 & "','" & K30 & "','" & L30 & "');" -> INSERT INTO `directory` (`order`, `office`, `displayname`, `title`, `ext`, `personalTel`, `directTel`, `email`, `contacttype`) VALUES ('29','4','Mississauga Office','1177 Central Parkway West, Golden Square, Unit 32, Mississauga, ON, L5C 4P3','--','--','T: (905) 896-0002','mississauga@livingrealtykw.com','Office Header');
A31: 30 | B31: MS | C31: LRI MS | D31: 4 | E31: Cassandra Pacitto | F31: Y | G31: Manager Mississauga Branch | H31: --- | I31: (905) 896-0002 | J31: --- | K31: cassandrapacitto@livingrealtykw.com | L31: Staff | M31: ="INSERT INTO `directory` (`order`, `office`, `displayname`, `title`, `ext`, `personalTel`, `directTel`, `email`, `contacttype`) VALUES ('" & A31 & "','" & D31 & "','" & E31 & "','" & G31 & "','" & H31 & "','" & I31 & "','" & J31 & "','" & K31 & "','" & L31 & "');" -> INSERT INTO `directory` (`order`, `office`, `displayname`, `title`, `ext`, `personalTel`, `directTel`, `email`, `contacttype`) VALUES ('30','4','Cassandra Pacitto','Manager Mississauga Branch','---','(905) 896-0002','---','cassandrapacitto@livingrealtykw.com','Staff');
A32: 31 | B32: MS | C32: LRI MS | D32: 4 | E32: Katie Wong | F32: Y | G32: Secretary | H32: --- | I32: --- | J32: (905) 896-0002 | K32: katiewong@livingrealtykw.com | L32: Staff | M32: ="INSERT INTO `directory` (`order`, `office`, `displayname`, `title`, `ext`, `personalTel`, `directTel`, `email`, `contacttype`) VALUES ('" & A32 & "','" & D32 & "','" & E32 & "','" & G32 & "','" & H32 & "','" & I32 & "','" & J32 & "','" & K32 & "','" & L32 & "');" -> INSERT INTO `directory` (`order`, `office`, `displayname`, `title`, `ext`, `personalTel`, `directTel`, `email`, `contacttype`) VALUES ('31','4','Katie Wong','Secretary','---','---','(905) 896-0002','katiewong@livingrealtykw.com','Staff');
A33: 32 | B33: MS | C33: LRI MS | D33: 4 | E33: Juliana Monize | F33: Y | G33: Secretary | H33: --- | I33: --- | J33: (905) 896-0002 | K33: julianamonize@livingrealtykw.com | L33: Staff | M33: ="INSERT INTO `directory` (`order`, `office`, `displayname`, `title`, `ext`, `personalTel`, `directTel`, `email`, `contacttype`) VALUES ('" & A33 & "','" & D33 & "','" & E33 & "','" & G33 & "','" & H33 & "','" & I33 & "','" & J33 & "','" & K33 & "','" & L33 & "');" -> INSERT INTO `directory` (`order`, `office`, `displayname`, `title`, `ext`, `personalTel`, `directTel`, `email`, `contacttype`) VALUES ('32','4','Juliana Monize','Secretary','---','---','(905) 896-0002','julianamonize@livingrealtykw.com','Staff');
A34: 33 | B34: WB | C34: LRI WB | D34: 5 | E34: Woodbine Office | F34: Y | G34: 8 Steelcase Road West, Markham, ON, L3R 1B2 | H34: -- | I34: -- | J34: T: (905) 474-0500 | K34: woodbine@livingrealtykw.com | L34: Office Header | M34: ="INSERT INTO `directory` (`order`, `office`, `displayname`, `title`, `ext`, `personalTel`, `directTel`, `email`, `contacttype`) VALUES ('" & A34 & "','" & D34 & "','" & E34 & "','" & G34 & "','" & H34 & "','" & I34 & "','" & J34 & "','" & K34 & "','" & L34 & "');" -> INSERT INTO `directory` (`order`, `office`, `displayname`, `title`, `ext`, `personalTel`, `directTel`, `email`, `contacttype`) VALUES ('33','5','Woodbine Office','8 Steelcase Road West, Markham, ON, L3R 1B2','--','--','T: (905) 474-0500','woodbine@livingrealtykw.com','Office Header');
A35: 34 | B35: WB | C35: LRI WB | D35: 5 | E35: Anita Huang | F35: Y | G35: Manager Woobine Branch | H35: 176 | I35: (416) 523-1888 | J35: --- | K35: anitahuang@livingrealtykw.com | L35: Staff | M35: ="INSERT INTO `directory` (`order`, `office`, `displayname`, `title`, `ext`, `personalTel`, `directTel`, `email`, `contacttype`) VALUES ('" & A35 & "','" & D35 & "','" & E35 & "','" & G35 & "','" & H35 & "','" & I35 & "','" & J35 & "','" & K35 & "','" & L35 & "');" -> INSERT INTO `directory` (`order`, `office`, `displayname`, `title`, `ext`, `personalTel`, `directTel`, `email`, `contacttype`) VALUES ('34','5','Anita Huang','Manager Woobine Branch','176','(416) 523-1888','---','anitahuang@livingrealtykw.com','Staff');
A36: 35 | B36: WB | C36: LRI WB | D36: 5 | E36: Savanna Joo | F36: Y | G36: Secretary | H36: 100 | I36: --- | J36: (905) 474-0500 | K36: savannajoo@livingrealtykw.com | L36: Staff | M36: ="INSERT INTO `directory` (`order`, `office`, `displayname`, `title`, `ext`, `personalTel`, `directTel`, `email`, `contacttype`) VALUES ('" & A36 & "','" & D36 & "','" & E36 & "','" & G36 & "','" & H36 & "','" & I36 & "','" & J36 & "','" & K36 & "','" & L36 & "');" -> INSERT INTO `directory` (`order`, `office`, `displayname`, `title`, `ext`, `personalTel`, `directTel`, `email`, `contacttype`) VALUES ('35','5','Savanna Joo','Secretary','100','---','(905) 474-0500','savannajoo@livingrealtykw.com','Staff');
A37: 36 | B37: WB | C37: LRI WB | D37: 5 | E37: Riley Lam | F37: Y | G37: Secretary | H37: 104 | I37: --- | J37: (905) 474-0500 | K37: rileylam@livingrealtykw.com | L37: Staff | M37: ="INSERT INTO `directory` (`order`, `office`, `displayname`, `title`, `ext`, `personalTel`, `directTel`, `email`, `contacttype`) VALUES ('" & A37 & "','" & D37 & "','" & E37 & "','" & G37 & "','" & H37 & "','" & I37 & "','" & J37 & "','" & K37 & "','" & L37 & "');" -> INSERT INTO `directory` (`order`, `office`, `displayname`, `title`, `ext`, `personalTel`, `directTel`, `email`, `contacttype`) VALUES ('36','5','Riley Lam','Secretary','104','---','(905) 474-0500','rileylam@livingrealtykw.com','Staff');
A38: 37 | B38: NY | C38: LRI YE | D38: 3 | E38: Yonge & Eglinton Office | F38: Y | G38: 2301 Yonge Street, Toronto, ON, M4P 2C6 | H38: -- | I38: -- | J38: T: (416) 223-8833 | K38: ye@livingrealtykw.com | L38: Office Header | M38: ="INSERT INTO `directory` (`order`, `office`, `displayname`, `title`, `ext`, `personalTel`, `directTel`, `email`, `contacttype`) VALUES ('" & A38 & "','" & D38 & "','" & E38 & "','" & G38 & "','" & H38 & "','" & I38 & "','" & J38 & "','" & K38 & "','" & L38 & "');" -> INSERT INTO `directory` (`order`, `office`, `displayname`, `title`, `ext`, `personalTel`, `directTel`, `email`, `contacttype`) VALUES ('37','3','Yonge & Eglinton Office','2301 Yonge Street, Toronto, ON, M4P 2C6','--','--','T: (416) 223-8833','ye@livingrealtykw.com','Office Header');
A39: 38 | B39: NY | C39: LRI YE | D39: 3 | E39: Tony Prochilo | F39: Y | G39: Manager Yonge & Eglinton | H39: --- | I39: (416) 576-6312 | J39: --- | K39: tonyprochilo@livingrealtykw.com | L39: Staff | M39: ="INSERT INTO `directory` (`order`, `office`, `displayname`, `title`, `ext`, `personalTel`, `directTel`, `email`, `contacttype`) VALUES ('" & A39 & "','" & D39 & "','" & E39 & "','" & G39 & "','" & H39 & "','" & I39 & "','" & J39 & "','" & K39 & "','" & L39 & "');" -> INSERT INTO `directory` (`order`, `office`, `displayname`, `title`, `ext`, `personalTel`, `directTel`, `email`, `contacttype`) VALUES ('38','3','Tony Prochilo ','Manager Yonge & Eglinton','---','(416) 576-6312','---','tonyprochilo@livingrealtykw.com','Staff');
A40: 39 | B40: NY | C40: LRI YE | D40: 3 | E40: Lydia Ng | F40: Y | G40: Secretary | H40: --- | I40: --- | J40: (416) 223-8833 | K40: lydiang@livingrealtykw.com | L40: Staff | M40: ="INSERT INTO `directory` (`order`, `office`, `displayname`, `title`, `ext`, `personalTel`, `directTel`, `email`, `contacttype`) VALUES ('" & A40 & "','" & D40 & "','" & E40 & "','" & G40 & "','" & H40 & "','" & I40 & "','" & J40 & "','" & K40 & "','" & L40 & "');" -> INSERT INTO `directory` (`order`, `office`, `displayname`, `title`, `ext`, `personalTel`, `directTel`, `email`, `contacttype`) VALUES ('39','3','Lydia Ng','Secretary','---','---','(416) 223-8833','lydiang@livingrealtykw.com','Staff');
...

Sheet Sorting
B1: Location Code
B2: HO
B3: NM
B4: NY
B5: MS
B6: WB
B7: YB
B8: IC
B9: HOLPI
B10: CT
B11: Eglinton
B12: EQ1
... B14: IHMG
